Workbook
Name birth1: '[1]Admin Population'!$C$16
Name hrs_supervision_after_first_yr: '[1]Admin Training & supervision'!$H$5
Name MMR: '[1]Admin Population'!$C$12
Name no_screened_pos_midwives_AN: '[1]Admin Population'!$C$40
Name No_visits_antenatal_period: '[1]Admin Screening & treatment'!$C$6
Name Probability_of_still_birth: '[1]Admin Population'!$C$11
Name prop_accept_treatment: '[1]Admin Population'!$C$63
Name prop_access_clinics_AN: '[1]Admin Population'!$C$23
Name prop_screened_pos_year_1_AN: '[1]Admin Population'!$C$42
Name prop_screened_year_1: '[1]Admin Population'!$C$28

Sheet inputs
C1: optional | D1: must be unique | H1: only if tunable | I1: only if tunable | J1: optional
B2: Section | C2: Subsection | D2: Variable name | E2: Default Value | F2: Is Tunable By User? | G2: Step Size | H2: Min range | I2: Max range | J2: Unit | K2: Text input | L2: Display name | M2: Tooltip | N2: Comments (note on the value, source of the default, etc.)
B3: Mothers' impact | C3: Cohort | D3: Live births | E3: 645273 | F3: Yes | G3: 1 | H3: 0 | I3: 60000000 | J3: Number | K3: Yes | L3: Live births | M3: insert tooltip here | N3: e.g., Calculated by muliplying birth rate w population
B4: Mothers' impact | C4: Cohort | D4: Still birth rate (per 1,000) | E4: 3.9 | F4: Yes | G4: 0.1 | H4: 0 | I4: 20 | J4: Rate | K4: No | L4: Still birth rate (per 1,000) | M4: insert tooltip here
B5: Mothers' impact | C5: Cohort | D5: Mortality probability during / after birth | E5: 0.0003 | F5: Yes | G5: 1e-05 | H5: 0 | I5: 0.1 | J5: Probability | K5: Yes | L5: Mortality probability during / after birth | M5: insert tooltip here
B6: Mothers' impact | C6: Cohort | D6: Mortality probability (women aged 15 to 39yrs) | E6: 0.0007 | F6: Yes | G6: 1e-05 | H6: 0 | I6: 0.1 | J6: Probability | K6: Yes | L6: Mortality probability (women aged 15 to 39yrs) | M6: insert tooltip here
B7: Mothers' impact | C7: With antenatal mental health problems | D7: Prevalence / probability antenatal depression (moderate and severe only) | E7: 0.2 | F7: Yes | G7: 0.1 | H7: 0 | I7: 100 | J7: Percentage | K7: No | L7: Prevalence antenatal depression (moderate or severe) | M7: insert tooltip here
B8: Mothers' impact | C8: With antenatal mental health problems | D8: Proportion of antenatal depression that is moderate depression | E8: 0.8 | F8: No | J8: Percentage | K8: No | L8: Proportion of antenatal depression that is moderate depression | M8: insert tooltip here
B9: Mothers' impact | C9: With antenatal mental health problems | D9: Proportion of antenatal depression that is severe depression | E9: 0.2 | F9: No | J9: Percentage | K9: No | L9: Proportion of antenatal depression that is severe depression | M9: insert tooltip here
B10: Mothers' impact | C10: With antenatal mental health problems | D10: Prevalence / probability antenatal anxiety (any) without depression | E10: 0.035 | F10: Yes | G10: 0.1 | H10: 0 | I10: 100 | J10: Percentage | K10: No | L10: Prevalence antenatal anxiety without depression | M10: insert tooltip here
B11: Mothers' impact | C11: With postnatal mental health problems | D11: Prevalence postnatal depression (moderate or severe) | E11: 0.2 | F11: Yes | G11: 0.1 | H11: 0 | I11: 100 | J11: Percentage | K11: No | L11: Prevalence postnatal depression (moderate or severe) | M11: insert tooltip here
B12: Mothers' impact | C12: With postnatal mental health problems | D12: Proportion of postnatal depression that is moderate depression | E12: 0.8 | F12: No | J12: Percentage | K12: No | L12: Proportion of postnatal depression that is moderate depression | M12: insert tooltip here
B13: Mothers' impact | C13: With postnatal mental health problems | D13: Proportion of postnatal depression that is severe depression | E13: 0.2 | F13: No | J13: Percentage | K13: No | L13: Proportion of postnatal depression that is severe depression | M13: insert tooltip here
B14: Mothers' impact | C14: With postnatal mental health problems | D14: Prevalence / probability postnatal anxiety (any) without depression | E14: 0.1 | F14: Yes | G14: 0.1 | H14: 0 | I14: 100 | J14: Percentage | K14: No | L14: Prevalence postnatal anxiety without depression | M14: insert tooltip here
B15: Mothers' impact | C15: With ongoing mental health problems | D15: Prevalence / probability ongoing depression | E15: 0.05 | F15: No | J15: Percentage | K15: No | L15: Prevalence ongoing depression | M15: insert tooltip here
B16: Mothers' impact | C16: With ongoing mental health problems | D16: Prevalence / probability ongoing anxiety | E16: 0.05 | F16: No | J16: Percentage | K16: No | L16: Prevalence ongoing anxiety | M16: insert tooltip here
B17: Mothers' impact | C17: With ongoing mental health problems | D17: Duration of perinatal mental health problems | E17: 0.25 | F17: No | J17: Yrs | K17: No | L17: Duration of perinatal mental health problems | M17: insert tooltip here
B18: Mothers' impact | C18: Disability Adjusted Life Years | D18: Disability weight for moderate depression | E18: 0.396 | F18: No | J18: Weight | K18: No | L18: Disability weight for moderate depression | M18: insert tooltip here
B19: Mothers' impact | C19: Disability Adjusted Life Years | D19: Disability weight for severe depression | E19: 0.658 | F19: No | J19: Weight | K19: No | L19: Disability weight for severe depression | M19: insert tooltip here
B20: Mothers' impact | C20: Disability Adjusted Life Years | D20: Disability weight for moderate anxiety | E20: 0.133 | F20: No | J20: Weight | K20: No | L20: Disability weight for moderate anxiety | M20: insert tooltip here
B21: Mothers' impact | C21: Quality Adjusted Life Years | D21: Health utility weight for moderate depression | E21: =1-E18 -> 0.604 | F21: No | J21: Weight | K21: No | L21: Health utility weight for moderate depression | M21: insert tooltip here
B22: Mothers' impact | C22: Quality Adjusted Life Years | D22: Health utility weight for severe depression | E22: =1-E19 -> 0.342 | F22: No | J22: Weight | K22: No | L22: Health utility weight for severe depression | M22: insert tooltip here
B23: Mothers' impact | C23: Quality Adjusted Life Years | D23: Health utility weight for moderate anxiety | E23: =1-E22 -> 0.658 | F23: No | J23: Weight | K23: No | L23: Health utility weight for moderate anxiety | M23: insert tooltip here
B24: Mothers' impact | C24: Years of Life Lost | D24: Suicide rate ante- and postnatal period (per 100,000) | E24: 5.5 | F24: Yes | G24: 0.1 | H24: 0 | I24: 20 | J24: Rate | K24: No | L24: Suicide rate ante- and postnatal period (per 100,000) | M24: insert tooltip here
B25: Mothers' impact | C25: Years of Life Lost | D25: Years of Life Lost due to suicide | E25: 60 | F25: No | J25: Yrs | K25: No | L25: Years of Life Lost due to suicide | M25: insert tooltip here
B26: Mothers' impact | C26: Valuing quality of life loss, in USD | D26: GDP per capita | E26: 7172 | F26: Yes | G26: 1 | H26: 0 | I26: 100000 | J26: Currency | K26: Yes | L26: GDP per capita | M26: insert tooltip here
B27: Mothers + children impact | C27: Valuing quality of life loss, in USD | D27: Weight for valuing DALY with GDP per capita | E27: 0.5 | F27: No | J27: Weight | K27: No | L27: Weight for valuing DALY with GDP per capita | M27: insert tooltip here
B28: Mothers' impact | C28: Valuing productivity loss, in USD | D28: Income decrement depression women per year, in USD | E28: 2217 | F28: Yes | G28: 1 | H28: 0 | I28: 6000 | J28: Currency | K28: Yes | L28: Income decrement depression women per year | M28: insert tooltip here
B29: Mothers' impact | C29: Valuing productivity loss, in USD | D29: Income decrement anxiety women per year, in USD | E29: 2217 | F29: Yes | G29: 1 | H29: 0 | I29: 6000 | J29: Currency | K29: Yes | L29: Income decrement anxiety women per year | M29: insert tooltip here
B30: Mothers + children impact | C30: Exchange rate | D30: Exchange rate Thai Bat USD | E30: =0.03 -> 0.03 | F30: N/A | J30: Rate | K30: No | L30: Exchange rate Thai Bat USD | M30: insert tooltip here
B31: Mothers + children impact | C31: Discounting | D31: Discount rate +1 | E31: 1.03 | F31: No | J31: Number | K31: No | L31: Discount rate +1 | M31: insert tooltip here
B32: Children's impact | C32: Mortality | D32: Mortality birth year | E32: 0.007 | F32: Yes | G32: 1e-05 | H32: 0 | I32: 0.03 | J32: Probability | K32: Yes | L32: Birth year | M32: insert tooltip here
B33: Children's impact | C33: Mortality | D33: Mortality Years 1 to 5 | E33: 0.0003 | F33: Yes | G33: 1e-05 | H33: 0 | I33: 0.03 | J33: Probability | K33: Yes | L33: Years 1 to 5 | M33: insert tooltip here
B34: Children's impact | C34: Mortality | D34: Mortality Years 6 to 10 | E34: 0.0003 | F34: Yes | G34: 1e-05 | H34: 0 | I34: 0.03 | J34: Probability | K34: Yes | L34: Years 6 to 10 | M34: insert tooltip here
B35: Children's impact | C35: Mortality | D35: Mortality Years 11 to 20 | E35: 0.0003 | F35: Yes | G35: 1e-05 | H35: 0 | I35: 0.03 | J35: Probability | K35: Yes | L35: Years 11 to 20 | M35: insert tooltip here
B36: Children's impact | C36: Mortality | D36: Mortality Years 21 to 25 | E36: 0.001 | F36: Yes | G36: 1e-05 | H36: 0 | I36: 0.03 | J36: Probability | K36: Yes | L36: Years 21 to 25 | M36: insert tooltip here
B37: Children's impact | C37: Mortality | D37: Mortality Years 26 to 30 | E37: 0.002 | F37: Yes | G37: 1e-05 | H37: 0 | I37: 0.03 | J37: Probability | K37: Yes | L37: Years 26 to 30 | M37: insert tooltip here
B38: Children's impact | C38: Mortality | D38: Mortality Years 31 to 40 | E38: 0.002 | F38: Yes | G38: 1e-05 | H38: 0 | I38: 0.03 | J38: Probability | K38: Yes | L38: Years 31 to 40 | M38: insert tooltip here
B39: Children's impact | C39: Exposure | D39: Prevalence of perinatal mental health condition impacting on child outcome 1 PRTB | E39: 0.2 | F39: No | J39: Probability | K39: No | L39: Prevalence of perinatal mental health condition impacting on child outcome 1 PRTB | M39: insert tooltip here | N39: PRTB = pre-term birth
B40: Children's impact | C40: Exposure | D40: Prevalence of perinatal mental health condition impacting on child outcome 2 LBW | E40: 0.2 | F40: No | J40: Probability | K40: No | L40: Prevalence of perinatal mental health condition impacting on child outcome 2 LBW | M40: insert tooltip here | N40: LBW = low birth weight
...

Sheet computations
A1: Section | B1: Subsection | C1: Variable Name | D1: Formula | E1: Formula expanded
A2: Mother impact | B2: Cohort | C2: Number of women antenatal period | D2: =inputs!E3/(1 - inputs!E4/1000) -> 647799.42 | E2: =_xlfn.FORMULATEXT(D2) -> =inputs!E3/(1 - inputs!E4/1000) | F2: This formula has been edited, it is now: live births / (1 – stillbirth rate) rather than live births * (1 + stillbirth rate). This is because the stillbirths are not included in live births and so live births does not represent 100% of all births.
A3: Mother impact | B3: Cohort | C3: Number of women postnatal period | D3: =inputs!E3-inputs!E5*inputs!E3 -> 645079.42 | E3: =_xlfn.FORMULATEXT(D3) -> =inputs!E3-inputs!E5*inputs!E3
A4: Mother impact | B4: Cohort | C4: Number of women Year + 1 | D4: =D3-inputs!$E$6*computations!D3 -> 644627.86 | E4: =_xlfn.FORMULATEXT(D4) -> =D3-inputs!$E$6*computations!D3
A5: Mother impact | B5: Cohort | C5: Number of women Year + 2 | D5: =D4-inputs!$E$6*D4 -> 644176.62 | E5: =_xlfn.FORMULATEXT(D5) -> =D4-inputs!$E$6*D4
A6: Mother impact | B6: Cohort | C6: Number of women Year + 3 | D6: =D5-inputs!$E$6*D5 -> 643725.7 | E6: =_xlfn.FORMULATEXT(D6) -> =D5-inputs!$E$6*D5
A7: Mother impact | B7: Cohort | C7: Number of women Year + 4 | D7: =D6-inputs!$E$6*D6 -> 643275.09 | E7: =_xlfn.FORMULATEXT(D7) -> =D6-inputs!$E$6*D6
A8: Mother impact | B8: Cohort | C8: Number of women Year + 5 | D8: =D7-inputs!$E$6*D7 -> 642824.8 | E8: =_xlfn.FORMULATEXT(D8) -> =D7-inputs!$E$6*D7
A9: Mother impact | B9: Cohort | C9: Number of women Year + 6 | D9: =D8-inputs!$E$6*D8 -> 642374.82 | E9: =_xlfn.FORMULATEXT(D9) -> =D8-inputs!$E$6*D8
A10: Mother impact | B10: Cohort | C10: Number of women Year + 7 | D10: =D9-inputs!$E$6*D9 -> 641925.16 | E10: =_xlfn.FORMULATEXT(D10) -> =D9-inputs!$E$6*D9
A11: Mother impact | B11: Cohort | C11: Number of women Year + 8 | D11: =D10-inputs!$E$6*D10 -> 641475.81 | E11: =_xlfn.FORMULATEXT(D11) -> =D10-inputs!$E$6*D10
A12: Mother impact | B12: Cohort | C12: Number of women Year + 9 | D12: =D11-inputs!$E$6*D11 -> 641026.78 | E12: =_xlfn.FORMULATEXT(D12) -> =D11-inputs!$E$6*D11
A13: Mother impact | B13: Cohort | C13: Number of women Year + 10 | D13: =D12-inputs!$E$6*D12 -> 640578.06 | E13: =_xlfn.FORMULATEXT(D13) -> =D12-inputs!$E$6*D12
A14: Mother impact | B14: Women with moderate depression | C14: Number women moderately depressed antenatal | D14: =D2*inputs!$E$7*inputs!$E$8 -> 103647.91 | E14: =_xlfn.FORMULATEXT(D14) -> =D2*inputs!$E$7*inputs!$E$8
A15: Mother impact | B15: Women with moderate depression | C15: Number women moderately depressed postnatal | D15: =D3*inputs!E11*inputs!E12 -> 103212.71 | E15: =_xlfn.FORMULATEXT(D15) -> =D3*inputs!E11*inputs!E12
A16: Mother impact | B16: Women with moderate depression | C16: Number women moderately depressed Year +1 | D16: =D4*inputs!$E$11*inputs!$E$12*inputs!$E$15 -> 5157.0229 | E16: =_xlfn.FORMULATEXT(D16) -> =D4*inputs!$E$11*inputs!$E$12*inputs!$E$15
A17: Mother impact | B17: Women with moderate depression | C17: Number women moderately depressed Year +2 | D17: =D5*inputs!$E$11*inputs!$E$12*inputs!$E$15 -> 5153.413 | E17: =_xlfn.FORMULATEXT(D17) -> =D5*inputs!$E$11*inputs!$E$12*inputs!$E$15
A18: Mother impact | B18: Women with moderate depression | C18: Number women moderately depressed Year +3 | D18: =D6*inputs!$E$11*inputs!$E$12*inputs!$E$15 -> 5149.8056 | E18: =_xlfn.FORMULATEXT(D18) -> =D6*inputs!$E$11*inputs!$E$12*inputs!$E$15
A19: Mother impact | B19: Women with moderate depression | C19: Number women moderately depressed Year +4 | D19: =D7*inputs!$E$11*inputs!$E$12*inputs!$E$15 -> 5146.2007 | E19: =_xlfn.FORMULATEXT(D19) -> =D7*inputs!$E$11*inputs!$E$12*inputs!$E$15
A20: Mother impact | B20: Women with moderate depression | C20: Number women moderately depressed Year +5 | D20: =D8*inputs!$E$11*inputs!$E$12*inputs!$E$15 -> 5142.5984 | E20: =_xlfn.FORMULATEXT(D20) -> =D8*inputs!$E$11*inputs!$E$12*inputs!$E$15
A21: Mother impact | B21: Women with moderate depression | C21: Number women moderately depressed Year +6 | D21: =D9*inputs!$E$11*inputs!$E$12*inputs!$E$15 -> 5138.9986 | E21: =_xlfn.FORMULATEXT(D21) -> =D9*inputs!$E$11*inputs!$E$12*inputs!$E$15
A22: Mother impact | B22: Women with moderate depression | C22: Number women moderately depressed Year +7 | D22: =D10*inputs!$E$11*inputs!$E$12*inputs!$E$15 -> 5135.4013 | E22: =_xlfn.FORMULATEXT(D22) -> =D10*inputs!$E$11*inputs!$E$12*inputs!$E$15
A23: Mother impact | B23: Women with moderate depression | C23: Number women moderately depressed Year +8 | D23: =D11*inputs!$E$11*inputs!$E$12*inputs!$E$15 -> 5131.8065 | E23: =_xlfn.FORMULATEXT(D23) -> =D11*inputs!$E$11*inputs!$E$12*inputs!$E$15
A24: Mother impact | B24: Women with moderate depression | C24: Number women moderately depressed Year +9 | D24: =D12*inputs!$E$11*inputs!$E$12*inputs!$E$15 -> 5128.2142 | E24: =_xlfn.FORMULATEXT(D24) -> =D12*inputs!$E$11*inputs!$E$12*inputs!$E$15
A25: Mother impact | B25: Women with moderate depression | C25: Number women moderately depressed Year +10 | D25: =D13*inputs!$E$11*inputs!$E$12*inputs!$E$15 -> 5124.6245 | E25: =_xlfn.FORMULATEXT(D25) -> =D13*inputs!$E$11*inputs!$E$12*inputs!$E$15
A26: Mother impact | B26: Women with severe depression | C26: Number women severely depressed antenatal | D26: =D2*inputs!E7*inputs!E9 -> 25911.977 | E26: =_xlfn.FORMULATEXT(D26) -> =D2*inputs!E7*inputs!E9
A27: Mother impact | B27: Women with severe depression | C27: Number women severly depressed postnatal | D27: =D3*inputs!E11*inputs!E13 -> 25803.177 | E27: =_xlfn.FORMULATEXT(D27) -> =D3*inputs!E11*inputs!E13
A28: Mother impact | B28: Women with severe depression | C28: Number women severly depressed Year +1 | D28: =D4*inputs!$E$11*inputs!$E$13*inputs!$E$15 -> 1289.2557 | E28: =_xlfn.FORMULATEXT(D28) -> =D4*inputs!$E$11*inputs!$E$13*inputs!$E$15
A29: Mother impact | B29: Women with severe depression | C29: Number women severly depressed Year +2 | D29: =D5*inputs!$E$11*inputs!$E$13*inputs!$E$15 -> 1288.3532 | E29: =_xlfn.FORMULATEXT(D29) -> =D5*inputs!$E$11*inputs!$E$13*inputs!$E$15
A30: Mother impact | B30: Women with severe depression | C30: Number women severly depressed Year +3 | D30: =D6*inputs!$E$11*inputs!$E$13*inputs!$E$15 -> 1287.4514 | E30: =_xlfn.FORMULATEXT(D30) -> =D6*inputs!$E$11*inputs!$E$13*inputs!$E$15
A31: Mother impact | B31: Women with severe depression | C31: Number women severly depressed Year +4 | D31: =D7*inputs!$E$11*inputs!$E$13*inputs!$E$15 -> 1286.5502 | E31: =_xlfn.FORMULATEXT(D31) -> =D7*inputs!$E$11*inputs!$E$13*inputs!$E$15
A32: Mother impact | B32: Women with severe depression | C32: Number women severly depressed Year +5 | D32: =D8*inputs!$E$11*inputs!$E$13*inputs!$E$15 -> 1285.6496 | E32: =_xlfn.FORMULATEXT(D32) -> =D8*inputs!$E$11*inputs!$E$13*inputs!$E$15
A33: Mother impact | B33: Women with severe depression | C33: Number women severly depressed Year +6 | D33: =D9*inputs!$E$11*inputs!$E$13*inputs!$E$15 -> 1284.7496 | E33: =_xlfn.FORMULATEXT(D33) -> =D9*inputs!$E$11*inputs!$E$13*inputs!$E$15
A34: Mother impact | B34: Women with severe depression | C34: Number women severly depressed Year +7 | D34: =D10*inputs!$E$11*inputs!$E$13*inputs!$E$15 -> 1283.8503 | E34: =_xlfn.FORMULATEXT(D34) -> =D10*inputs!$E$11*inputs!$E$13*inputs!$E$15
A35: Mother impact | B35: Women with severe depression | C35: Number women severly depressed Year +8 | D35: =D11*inputs!$E$11*inputs!$E$13*inputs!$E$15 -> 1282.9516 | E35: =_xlfn.FORMULATEXT(D35) -> =D11*inputs!$E$11*inputs!$E$13*inputs!$E$15
A36: Mother impact | B36: Women with severe depression | C36: Number women severly depressed Year +9 | D36: =D12*inputs!$E$11*inputs!$E$13*inputs!$E$15 -> 1282.0536 | E36: =_xlfn.FORMULATEXT(D36) -> =D12*inputs!$E$11*inputs!$E$13*inputs!$E$15
A37: Mother impact | B37: Women with severe depression | C37: Number women severly depressed Year +10 | D37: =D13*inputs!$E$11*inputs!$E$13*inputs!$E$15 -> 1281.1561 | E37: =_xlfn.FORMULATEXT(D37) -> =D13*inputs!$E$11*inputs!$E$13*inputs!$E$15
A38: Mother impact | B38: Women with anxiety | C38: Number women anxious antenatal | D38: =D2*inputs!E10 -> 22672.98 | E38: =_xlfn.FORMULATEXT(D38) -> =D2*inputs!E10
A39: Mother impact | B39: Women with anxiety | C39: Number women anxious postnatal | D39: =D3*inputs!E14 -> 64507.942 | E39: =_xlfn.FORMULATEXT(D39) -> =D3*inputs!E14
A40: Mother impact | B40: Women with anxiety | C40: Number women anxious Year +1 | D40: =D4*inputs!$E$14*inputs!$E$16 -> 3223.1393 | E40: =_xlfn.FORMULATEXT(D40) -> =D4*inputs!$E$14*inputs!$E$16
...

Sheet outputs
B2: Section | C2: Subsection | D2: Variable Name | E2: Formula
B4: DALY loss Mothers depression | C4: Mothers impact | D4: Mothers DALY loss mothers depression | E4: =SUM(computations!D51:D74) -> 52432.397
B5: DALY loss Mothers depression in USD | C5: Mothers impact | D5: Mothers DALY loss mothers depression in USD | E5: =SUM(computations!D88:D111) -> 1.8802258e+08
B6: DALY loss Mothers anxiety | C6: Mothers impact | D6: Mothers DALY loss mothers anxiety | E6: =SUM(computations!D75:D87) -> 10642.435
B7: DALY loss Mothers anxiety in USD | C7: Mothers impact | D7: Mothers DALY loss mothers anxiety in USD | E7: =SUM(computations!D112:D123) -> 22864101
B8: DALY loss Mothers suicide | C8: Mothers impact | D8: Mothers DALY loss mothers suicide | E8: =computations!D87 -> 4266.5002
B9: DALY loss Mothers suicide in USD | C9: Mothers impact | D9: Mothers DALY loss mothers suicide in USD | E9: =computations!D124 -> 15299670
B10: Income loss Mothers depression in USD | C10: Mothers impact | D10: Mothers income loss mothers depression in USD | E10: =SUM(computations!D125:D136) -> 6.8293735e+08
B11: Income loss Mothers anxiety in USD | C11: Mothers impact | D11: Mothers income loss mothers anxiety in USD | E11: =SUM(computations!D137:D148) -> 2.4811754e+08
B12: DALY loss Children | C12: Childrens impact | D12: Childrens DALY loss total | E12: =SUM(computations!D355:D499) -> 185152.88
B13: DALY loss Children | C13: Childrens impact | D13: Childrens DALY loss outcome 1
B14: DALY loss Children | C14: Childrens impact | D14: Childrens DALY loss outcome 2
B15: DALY loss Children | C15: Childrens impact | D15: Childrens DALY loss outcome 3
B16: DALY loss Children | C16: Childrens impact | D16: Childrens DALY loss outcome 4
B17: DALY loss Children | C17: Childrens impact | D17: Childrens DALY loss outcome 5
B18: DALY loss Children | C18: Childrens impact | D18: Childrens DALY loss outcome 6
B19: DALY loss Children | C19: Childrens impact | D19: Childrens DALY loss outcome 7
B20: DALY loss Children | C20: Childrens impact | D20: Childrens DALY loss outcome 8
B21: DALY loss Children | C21: Childrens impact | D21: Childrens DALY loss outcome 9
B22: DALY loss Children | C22: Childrens impact | D22: Childrens DALY loss outcome 10
B23: DALY loss Children | C23: Childrens impact | D23: Childrens DALY loss outcome 11
B24: DALY loss Children in USD | C24: Childrens impact | D24: Childrens DALY loss in USD total | E24: =SUM(computations!D500:D644) -> 6.6395823e+08 | G24: Mother's DALY
B25: DALY loss Children in USD | C25: Childrens impact | D25: Childrens DALY loss in USD outcome 1
B26: DALY loss Children in USD | C26: Childrens impact | D26: Childrens DALY loss in USD outcome 2
B27: DALY loss Children in USD | C27: Childrens impact | D27: Childrens DALY loss in USD outcome 3
B28: DALY loss Children in USD | C28: Childrens impact | D28: Childrens DALY loss in USD outcome 4
B29: DALY loss Children in USD | C29: Childrens impact | D29: Childrens DALY loss in USD outcome 5
B30: DALY loss Children in USD | C30: Childrens impact | D30: Childrens DALY loss in USD outcome 6
B31: DALY loss Children in USD | C31: Childrens impact | D31: Childrens DALY loss in USD outcome 7
B32: DALY loss Children in USD | C32: Childrens impact | D32: Childrens DALY loss in USD outcome 8
B33: DALY loss Children in USD | C33: Childrens impact | D33: Childrens DALY loss in USD outcome 9
B34: DALY loss Children in USD | C34: Childrens impact | D34: Childrens DALY loss in USD outcome 10
B35: DALY loss Children in USD | C35: Childrens impact | D35: Childrens DALY loss in USD outcome 11
B36: Income loss Children in USD | C36: Childrens impact | D36: Childrens income loss in USD total | E36: =SUM(computations!D645:D744) -> 2.1637171e+08 | G36: =E7+E5+E9 -> 2.2618635e+08
B37: Income loss Children in USD | C37: Childrens impact | D37: Childrens income loss in USD outcome 7
B38: Income loss Children in USD | C38: Childrens impact | D38: Childrens income loss in USD outcome 9
B39: Income loss Children in USD | C39: Childrens impact | D39: Childrens income loss in USD outcome 10
B40: Income loss Children in USD | C40: Childrens impact | D40: Childrens income loss in USD outcome 11
B41: Healthcare expenditure children | C41: Childrens impact | D41: Childrens healthcare cost Age 0 to 1 in USD | E41: =SUM(computations!D745:D751) -> 58438963 | G41: Mother's Income loss
B42: Total cost mothers | C42: Total cost mothers | D42: Total cost mothers | E42: =E5+E7+E9+E10+E11 -> 1.1572412e+09 | G42: =E10+E11 -> 9.3105489e+08
...
